<?xml version="1.0" encoding="UTF-8" ?>
<mujoco model="piston_arena">
    <compiler angle="degree" coordinate="global" inertiafromgeom="true"/>
    <default>
        <joint armature="1" damping="1"/>
        <geom conaffinity="1" condim="1" contype="1" margin="0.001" material="geom0" rgba="0.8 0.6 0.4 1" solimp="0.8 0.8 0.01" solref="0.02 1"/>
        <position ctrllimited="true" ctrlrange="0 3"/>
    </default>
    <option integrator="RK4" timestep="0.002"/>
    <visual>
        <map znear="0.02"/>
    </visual>
    <worldbody>
        <light cutoff="100" diffuse="1 1 1" dir="0 0 -1.3" directional="true" exponent="1" pos="0 0 1.3" specular="0.1 0.1 0.1"/>
        <geom type="plane" name="floor" size="20 20 0.01" pos="0 0 0" rgba="0.8 0.9 0.8 1" material="MatPlane" conaffinity="1" condim="3" />

        <geom type="box" name="stage" size="1.5 1.5 0.05" pos="0 0 0" rgba="0.8 0.9 0.8 1" material="geom0" conaffinity="1" condim="3" />


        <body>
            <geom type="box" pos="1 1 0.5" size="0.4 0.4 0.5" material="geom1"/>
        </body>
        <body>
            <geom type="box" pos="1 0 0.5" size="0.4 0.4 0.5" material="geom1"/>
        </body>
        <body>
            <geom type="box" pos="0 0 0.5" size="0.4 0.4 0.5" material="geom1"/>
        </body>
        <body>
            <geom type="box" pos="-1 -1 0.5" size="0.4 0.4 0.5" material="geom1"/>
        </body>

        <body name="piston0">
            <joint name="piston0-slider" type="slide" axis="0 -1 0" damping="1000"/>
            <geom type="capsule" fromto="1 4 0.5 1 1.8 0.5" size="0.1" material="geom2"/>
            <site name="piston_tip0" pos="1 1.8 0.5" type="box" group="4" size="0.2 0.2 0.2"/>
        </body>

        <body name="piston1">
            <joint name="piston1-slider" type="slide" axis="0 -1 0" damping="1000"/>
            <geom type="capsule" fromto="0 4 0.5 0 1.8 0.5" size="0.1" material="geom2"/>
            <site name="piston_tip1" pos="0 1.8 0.5" type="box" group="4" size="0.2 0.2 0.2"/>
        </body>

        <body name="piston2">
            <joint name="piston2-slider" type="slide" axis="0 -1 0" damping="1000"/>
            <geom type="capsule" fromto="-1 4 0.5 -1 1.8 0.5" size="0.1" material="geom2"/>
            <site name="piston_tip2" pos="-1 1.8 0.5" type="box" group="4" size="0.2 0.2 0.2"/>
        </body>


        <body name="piston3">
            <joint name="piston3-slider" type="slide" axis="-1 0 0" damping="1000"/>
            <geom type="capsule" fromto="1.8 1 0.2 4 1 0.2 " size="0.1" material="geom2"/>
            <site name="piston_tip3" pos="1.8 1 0.2" type="box" group="4" size="0.2 0.2 0.2"/>
        </body>

        <body name="piston4">
            <joint name="piston4-slider" type="slide" axis="-1 0 0" damping="1000"/>
            <geom type="capsule" fromto="1.8 0 0.2 4 0 0.2 " size="0.1" material="geom2"/>
            <site name="piston_tip4" pos="1.8 0 0.2" type="box" group="4" size="0.2 0.2 0.2"/>
        </body>

        <body name="piston5">
            <joint name="piston5-slider" type="slide" axis="-1 0 0" damping="1000"/>
            <geom type="capsule" fromto="1.8 -1 0.2 4 -1 0.2 " size="0.1" material="geom2"/>
            <site name="piston_tip5" pos="1.8 -1 0.2" type="box" group="4" size="0.2 0.2 0.2"/>
        </body>


        <body name="piston6">
            <joint name="piston6-slider" type="slide" axis="0 1 0" damping="1000"/>
            <geom type="capsule" fromto="1 -4 0.5 1 -1.8 0.5" size="0.1" material="geom2"/>
            <site name="piston_tip6" pos="1 -1.8 0.5" type="box" group="4" size="0.2 0.2 0.2"/>
        </body>

        <body name="piston7">
            <joint name="piston7-slider" type="slide" axis="0 1 0" damping="1000"/>
            <geom type="capsule" fromto="0 -4 0.5 0 -1.8 0.5" size="0.1" material="geom2"/>
            <site name="piston_tip7" pos="0 -1.8 0.5" type="box" group="4" size="0.2 0.2 0.2"/>
        </body>

        <body name="piston8">
            <joint name="piston8-slider" type="slide" axis="0 1 0" damping="1000"/>
            <geom type="capsule" fromto="-1 -4 0.5 -1 -1.8 0.5" size="0.1" material="geom2"/>
            <site name="piston_tip8" pos="-1 -1.8 0.5" type="box" group="4" size="0.2 0.2 0.2"/>
        </body>




    </worldbody>

    <actuator>
        <position joint="piston0-slider" kp="10000"/>
        <position joint="piston1-slider" kp="10000"/>
        <position joint="piston2-slider" kp="10000"/>
        <position joint="piston3-slider" kp="10000"/>
        <position joint="piston4-slider" kp="10000"/>
        <position joint="piston5-slider" kp="10000"/>
        <position joint="piston6-slider" kp="10000"/>
        <position joint="piston7-slider" kp="10000"/>
        <position joint="piston8-slider" kp="10000"/>
    </actuator>

    <sensor>
        <touch name="s_piston0" site="piston_tip0"/>
        <touch name="s_piston1" site="piston_tip1"/>
        <touch name="s_piston2" site="piston_tip2"/>
        <touch name="s_piston3" site="piston_tip3"/>
        <touch name="s_piston4" site="piston_tip4"/>
        <touch name="s_piston5" site="piston_tip5"/>
        <touch name="s_piston6" site="piston_tip6"/>
        <touch name="s_piston7" site="piston_tip7"/>
        <touch name="s_piston8" site="piston_tip8"/>
    </sensor>

    <asset>
        <texture name="texplane" builtin="checker" type="2d" height="100" width="100" rgb1="0 0 0" rgb2="0.8 0.8 0.8"/>
        <material name="MatPlane" reflectance="0.5" shininess="1" specular="1" texrepeat="60 60" texture="texplane"/>
        <texture builtin="flat" height="1278" mark="cross" markrgb="1 1 1" name="texgeom0" random="0.01" rgb1="0.8 0.6 0.4" rgb2="0.8 0.6 0.4" type="cube" width="127"/>
        <material name="geom0" texture="texgeom0" texuniform="true"/>
        <texture builtin="flat" height="1278" mark="cross" markrgb="1 1 1" name="texgeom1" random="0.01" rgb1="0.4 0.8 0.6" rgb2="0.4 0.8 0.6" type="cube" width="127"/>
        <material name="geom1" texture="texgeom1" texuniform="true"/>
        <texture builtin="flat" height="1278" mark="cross" markrgb="1 1 1" name="texgeom2" random="0.01" rgb1="1.0 0.2 0.2" rgb2="1.0 0.2 0.2" type="cube" width="127"/>
        <material name="geom2" texture="texgeom2" texuniform="true" reflectance="10.0" shininess="10.0"/>
    </asset>
</mujoco>